Workbook

Sheet Assignment 2
A5: 1)
A7: Monthly risk-free rate | B7: 0.0005
A11: From Assignment 1 Question 4
B12: NVIDIA | C12: MICROSOFT | D12: APPLE | E12: AMAZON.COM | F12: JOHNSON & JOHNSON | G12: ALPHABET 'A' | H12: COCA COLA
A13: Average Arithmetic Return | B13: =AVERAGE('Main Data'!Q3:Q188) -> 0.041658203 | C13: =AVERAGE('Main Data'!R3:R188) -> 0.017852502 | D13: =AVERAGE('Main Data'!S3:S188) -> 0.021382857 | E13: =AVERAGE('Main Data'!T3:T188) -> 0.023228866 | F13: =AVERAGE('Main Data'!U3:U188) -> 0.0061560788 | G13: =AVERAGE('Main Data'!V3:V188) -> 0.016955931 | H13: =AVERAGE('Main Data'!W3:W188) -> 0.0059154238
A14: Standartdeviation | B14: =_xlfn.STDEV.S('Main Data'!Q3:Q188) -> 0.13054214 | C14: =_xlfn.STDEV.S('Main Data'!R3:R188) -> 0.062629545 | D14: =_xlfn.STDEV.S('Main Data'!S3:S188) -> 0.076642979 | E14: =_xlfn.STDEV.S('Main Data'!T3:T188) -> 0.085901611 | F14: =_xlfn.STDEV.S('Main Data'!U3:U188) -> 0.044096799 | G14: =_xlfn.STDEV.S('Main Data'!V3:V188) -> 0.071216157 | H14: =_xlfn.STDEV.S('Main Data'!W3:W188) -> 0.043890976
A16: Weights | E16: Covariance Matrix
A17: {=TRANSPOSE(B12:H12)} -> NVIDIA | B17: 0.0090913556 | F17: 1 | G17: =F17+1 -> 2 | H17: =G17+1 -> 3 | I17: =H17+1 -> 4 | J17: =I17+1 -> 5 | K17: =J17+1 -> 6 | L17: =K17+1 -> 7
A18: MICROSOFT | B18: 0.087470314 | F18: NVIDIA | G18: MICROSOFT | H18: APPLE | I18: AMAZON.COM | J18: JOHNSON & JOHNSON | K18: ALPHABET 'A' | L18: COCA COLA
A19: APPLE | B19: 0.018523181 | D19: =F17 -> 1 | E19: NVIDIA | F19: =_xlfn.COVARIANCE.S(INDEX('Main Data'!$Q$3:$W$188,0,'Assignment 2'!F$17),INDEX('Main Data'!$Q$3:$W$188,0,'Assignment 2'!$D19)) -> 0.017041251 | G19: =_xlfn.COVARIANCE.S(INDEX('Main Data'!$Q$3:$W$188,0,'Assignment 2'!G$17),INDEX('Main Data'!$Q$3:$W$188,0,'Assignment 2'!$D19)) -> 0.0040918541 | H19: =_xlfn.COVARIANCE.S(INDEX('Main Data'!$Q$3:$W$188,0,'Assignment 2'!H$17),INDEX('Main Data'!$Q$3:$W$188,0,'Assignment 2'!$D19)) -> 0.0044467757 | I19: =_xlfn.COVARIANCE.S(INDEX('Main Data'!$Q$3:$W$188,0,'Assignment 2'!I$17),INDEX('Main Data'!$Q$3:$W$188,0,'Assignment 2'!$D19)) -> 0.004896828 | J19: =_xlfn.COVARIANCE.S(INDEX('Main Data'!$Q$3:$W$188,0,'Assignment 2'!J$17),INDEX('Main Data'!$Q$3:$W$188,0,'Assignment 2'!$D19)) -> 0.00058989063 | K19: =_xlfn.COVARIANCE.S(INDEX('Main Data'!$Q$3:$W$188,0,'Assignment 2'!K$17),INDEX('Main Data'!$Q$3:$W$188,0,'Assignment 2'!$D19)) -> 0.0037177492 | L19: =_xlfn.COVARIANCE.S(INDEX('Main Data'!$Q$3:$W$188,0,'Assignment 2'!L$17),INDEX('Main Data'!$Q$3:$W$188,0,'Assignment 2'!$D19)) -> 0.0001532048
A20: AMAZON.COM | B20: 0.015583359 | D20: =D19+1 -> 2 | E20: MICROSOFT | F20: =_xlfn.COVARIANCE.S(INDEX('Main Data'!$Q$3:$W$188,0,'Assignment 2'!F$17),INDEX('Main Data'!$Q$3:$W$188,0,'Assignment 2'!$D20)) -> 0.0040918541 | G20: =_xlfn.COVARIANCE.S(INDEX('Main Data'!$Q$3:$W$188,0,'Assignment 2'!G$17),INDEX('Main Data'!$Q$3:$W$188,0,'Assignment 2'!$D20)) -> 0.0039224598 | H20: =_xlfn.COVARIANCE.S(INDEX('Main Data'!$Q$3:$W$188,0,'Assignment 2'!H$17),INDEX('Main Data'!$Q$3:$W$188,0,'Assignment 2'!$D20)) -> 0.0023275216 | I20: =_xlfn.COVARIANCE.S(INDEX('Main Data'!$Q$3:$W$188,0,'Assignment 2'!I$17),INDEX('Main Data'!$Q$3:$W$188,0,'Assignment 2'!$D20)) -> 0.002789958 | J20: =_xlfn.COVARIANCE.S(INDEX('Main Data'!$Q$3:$W$188,0,'Assignment 2'!J$17),INDEX('Main Data'!$Q$3:$W$188,0,'Assignment 2'!$D20)) -> 0.00080230453 | K20: =_xlfn.COVARIANCE.S(INDEX('Main Data'!$Q$3:$W$188,0,'Assignment 2'!K$17),INDEX('Main Data'!$Q$3:$W$188,0,'Assignment 2'!$D20)) -> 0.0024488715 | L20: =_xlfn.COVARIANCE.S(INDEX('Main Data'!$Q$3:$W$188,0,'Assignment 2'!L$17),INDEX('Main Data'!$Q$3:$W$188,0,'Assignment 2'!$D20)) -> 0.00077626798
A21: JOHNSON & JOHNSON | B21: 0.39340158 | D21: =D20+1 -> 3 | E21: APPLE | F21: =_xlfn.COVARIANCE.S(INDEX('Main Data'!$Q$3:$W$188,0,'Assignment 2'!F$17),INDEX('Main Data'!$Q$3:$W$188,0,'Assignment 2'!$D21)) -> 0.0044467757 | G21: =_xlfn.COVARIANCE.S(INDEX('Main Data'!$Q$3:$W$188,0,'Assignment 2'!G$17),INDEX('Main Data'!$Q$3:$W$188,0,'Assignment 2'!$D21)) -> 0.0023275216 | H21: =_xlfn.COVARIANCE.S(INDEX('Main Data'!$Q$3:$W$188,0,'Assignment 2'!H$17),INDEX('Main Data'!$Q$3:$W$188,0,'Assignment 2'!$D21)) -> 0.0058741462 | I21: =_xlfn.COVARIANCE.S(INDEX('Main Data'!$Q$3:$W$188,0,'Assignment 2'!I$17),INDEX('Main Data'!$Q$3:$W$188,0,'Assignment 2'!$D21)) -> 0.0030919181 | J21: =_xlfn.COVARIANCE.S(INDEX('Main Data'!$Q$3:$W$188,0,'Assignment 2'!J$17),INDEX('Main Data'!$Q$3:$W$188,0,'Assignment 2'!$D21)) -> 0.00090740178 | K21: =_xlfn.COVARIANCE.S(INDEX('Main Data'!$Q$3:$W$188,0,'Assignment 2'!K$17),INDEX('Main Data'!$Q$3:$W$188,0,'Assignment 2'!$D21)) -> 0.0022130299 | L21: =_xlfn.COVARIANCE.S(INDEX('Main Data'!$Q$3:$W$188,0,'Assignment 2'!L$17),INDEX('Main Data'!$Q$3:$W$188,0,'Assignment 2'!$D21)) -> 0.0008973851
A22: ALPHABET 'A' | B22: 0.092743672 | D22: =D21+1 -> 4 | E22: AMAZON.COM | F22: =_xlfn.COVARIANCE.S(INDEX('Main Data'!$Q$3:$W$188,0,'Assignment 2'!F$17),INDEX('Main Data'!$Q$3:$W$188,0,'Assignment 2'!$D22)) -> 0.004896828 | G22: =_xlfn.COVARIANCE.S(INDEX('Main Data'!$Q$3:$W$188,0,'Assignment 2'!G$17),INDEX('Main Data'!$Q$3:$W$188,0,'Assignment 2'!$D22)) -> 0.002789958 | H22: =_xlfn.COVARIANCE.S(INDEX('Main Data'!$Q$3:$W$188,0,'Assignment 2'!H$17),INDEX('Main Data'!$Q$3:$W$188,0,'Assignment 2'!$D22)) -> 0.0030919181 | I22: =_xlfn.COVARIANCE.S(INDEX('Main Data'!$Q$3:$W$188,0,'Assignment 2'!I$17),INDEX('Main Data'!$Q$3:$W$188,0,'Assignment 2'!$D22)) -> 0.0073790868 | J22: =_xlfn.COVARIANCE.S(INDEX('Main Data'!$Q$3:$W$188,0,'Assignment 2'!J$17),INDEX('Main Data'!$Q$3:$W$188,0,'Assignment 2'!$D22)) -> 0.00080041925 | K22: =_xlfn.COVARIANCE.S(INDEX('Main Data'!$Q$3:$W$188,0,'Assignment 2'!K$17),INDEX('Main Data'!$Q$3:$W$188,0,'Assignment 2'!$D22)) -> 0.003372031 | L22: =_xlfn.COVARIANCE.S(INDEX('Main Data'!$Q$3:$W$188,0,'Assignment 2'!L$17),INDEX('Main Data'!$Q$3:$W$188,0,'Assignment 2'!$D22)) -> 0.00057060661
A23: COCA COLA | B23: 0.38318654 | D23: =D22+1 -> 5 | E23: JOHNSON & JOHNSON | F23: =_xlfn.COVARIANCE.S(INDEX('Main Data'!$Q$3:$W$188,0,'Assignment 2'!F$17),INDEX('Main Data'!$Q$3:$W$188,0,'Assignment 2'!$D23)) -> 0.00058989063 | G23: =_xlfn.COVARIANCE.S(INDEX('Main Data'!$Q$3:$W$188,0,'Assignment 2'!G$17),INDEX('Main Data'!$Q$3:$W$188,0,'Assignment 2'!$D23)) -> 0.00080230453 | H23: =_xlfn.COVARIANCE.S(INDEX('Main Data'!$Q$3:$W$188,0,'Assignment 2'!H$17),INDEX('Main Data'!$Q$3:$W$188,0,'Assignment 2'!$D23)) -> 0.00090740178 | I23: =_xlfn.COVARIANCE.S(INDEX('Main Data'!$Q$3:$W$188,0,'Assignment 2'!I$17),INDEX('Main Data'!$Q$3:$W$188,0,'Assignment 2'!$D23)) -> 0.00080041925 | J23: =_xlfn.COVARIANCE.S(INDEX('Main Data'!$Q$3:$W$188,0,'Assignment 2'!J$17),INDEX('Main Data'!$Q$3:$W$188,0,'Assignment 2'!$D23)) -> 0.0019445276 | K23: =_xlfn.COVARIANCE.S(INDEX('Main Data'!$Q$3:$W$188,0,'Assignment 2'!K$17),INDEX('Main Data'!$Q$3:$W$188,0,'Assignment 2'!$D23)) -> 0.00049723415 | L23: =_xlfn.COVARIANCE.S(INDEX('Main Data'!$Q$3:$W$188,0,'Assignment 2'!L$17),INDEX('Main Data'!$Q$3:$W$188,0,'Assignment 2'!$D23)) -> 0.0010208443
A24: SUM | B24: =SUM(B17:B23) -> 1 | D24: =D23+1 -> 6 | E24: ALPHABET 'A' | F24: =_xlfn.COVARIANCE.S(INDEX('Main Data'!$Q$3:$W$188,0,'Assignment 2'!F$17),INDEX('Main Data'!$Q$3:$W$188,0,'Assignment 2'!$D24)) -> 0.0037177492 | G24: =_xlfn.COVARIANCE.S(INDEX('Main Data'!$Q$3:$W$188,0,'Assignment 2'!G$17),INDEX('Main Data'!$Q$3:$W$188,0,'Assignment 2'!$D24)) -> 0.0024488715 | H24: =_xlfn.COVARIANCE.S(INDEX('Main Data'!$Q$3:$W$188,0,'Assignment 2'!H$17),INDEX('Main Data'!$Q$3:$W$188,0,'Assignment 2'!$D24)) -> 0.0022130299 | I24: =_xlfn.COVARIANCE.S(INDEX('Main Data'!$Q$3:$W$188,0,'Assignment 2'!I$17),INDEX('Main Data'!$Q$3:$W$188,0,'Assignment 2'!$D24)) -> 0.003372031 | J24: =_xlfn.COVARIANCE.S(INDEX('Main Data'!$Q$3:$W$188,0,'Assignment 2'!J$17),INDEX('Main Data'!$Q$3:$W$188,0,'Assignment 2'!$D24)) -> 0.00049723415 | K24: =_xlfn.COVARIANCE.S(INDEX('Main Data'!$Q$3:$W$188,0,'Assignment 2'!K$17),INDEX('Main Data'!$Q$3:$W$188,0,'Assignment 2'!$D24)) -> 0.0050717411 | L24: =_xlfn.COVARIANCE.S(INDEX('Main Data'!$Q$3:$W$188,0,'Assignment 2'!L$17),INDEX('Main Data'!$Q$3:$W$188,0,'Assignment 2'!$D24)) -> 0.00078176953
D25: =D24+1 -> 7 | E25: COCA COLA | F25: =_xlfn.COVARIANCE.S(INDEX('Main Data'!$Q$3:$W$188,0,'Assignment 2'!F$17),INDEX('Main Data'!$Q$3:$W$188,0,'Assignment 2'!$D25)) -> 0.0001532048 | G25: =_xlfn.COVARIANCE.S(INDEX('Main Data'!$Q$3:$W$188,0,'Assignment 2'!G$17),INDEX('Main Data'!$Q$3:$W$188,0,'Assignment 2'!$D25)) -> 0.00077626798 | H25: =_xlfn.COVARIANCE.S(INDEX('Main Data'!$Q$3:$W$188,0,'Assignment 2'!H$17),INDEX('Main Data'!$Q$3:$W$188,0,'Assignment 2'!$D25)) -> 0.0008973851 | I25: =_xlfn.COVARIANCE.S(INDEX('Main Data'!$Q$3:$W$188,0,'Assignment 2'!I$17),INDEX('Main Data'!$Q$3:$W$188,0,'Assignment 2'!$D25)) -> 0.00057060661 | J25: =_xlfn.COVARIANCE.S(INDEX('Main Data'!$Q$3:$W$188,0,'Assignment 2'!J$17),INDEX('Main Data'!$Q$3:$W$188,0,'Assignment 2'!$D25)) -> 0.0010208443 | K25: =_xlfn.COVARIANCE.S(INDEX('Main Data'!$Q$3:$W$188,0,'Assignment 2'!K$17),INDEX('Main Data'!$Q$3:$W$188,0,'Assignment 2'!$D25)) -> 0.00078176953 | L25: =_xlfn.COVARIANCE.S(INDEX('Main Data'!$Q$3:$W$188,0,'Assignment 2'!L$17),INDEX('Main Data'!$Q$3:$W$188,0,'Assignment 2'!$D25)) -> 0.0019264178
A28: Variance Portfolio | B28: {=MMULT(MMULT(TRANSPOSE($B$17:$B$23),$F$19:$L$25),$B$17:$B$23)} -> 0.001307091
A29: Expected return Portfoli | B29: {=MMULT($B$13:$H$13,$B$17:$B$23)} -> 0.008959433
A30: Standard Deviation Portfolio | B30: =SQRT(B28) -> 0.036153713
A36: 2)
B42: MAXIMAZING RETURN | M42: MINIMIZING RETURN
B44: MIN VAR | C44: Weights 2 | D44: Weights 3 | E44: Weights 4 | F44: Weights 5 | G44: Weights 6 | H44: Weights 7 | I44: Weights 8 | J44: Weights 9 | K44: Weights 10 | M44: Weights 11 | N44: Weights 12 | O44: Weights 13 | P44: Weights 14 | Q44: Weights 15 | R44: Weights 16 | S44: Weights 17 | T44: Weights 18 | U44: Weights 19
B45: 0.0090913808 | C45: 0.094849811 | D45: 0.14336048 | E45: 0.18199078 | F45: 0.21653001 | G45: 0.2496009 | H45: 0.27979268 | I45: 0.30965511 | J45: 0.47650404 | K45: 0.58291652 | M45: -0.07660325 | N45: -0.12451404 | O45: -0.16402511 | P45: -0.19877536 | Q45: -0.23110562 | R45: -0.26179296 | S45: -0.29026573 | T45: -0.45783482 | U45: -0.56419218
B46: 0.087470974 | C46: 0.11098357 | D46: 0.12454783 | E46: 0.13506873 | F46: 0.14657952 | G46: 0.15274564 | H46: 0.16380105 | I46: 0.1709387 | J46: 0.21322696 | K46: 0.24877011 | M46: 0.063314816 | N46: 0.04901337 | O46: 0.038627715 | P46: 0.029333055 | Q46: 0.017785388 | R46: 0.011753869 | S46: 0.0033261241 | T46: -0.044570692 | U46: -0.073117161
B47: 0.018523127 | C47: 0.080840352 | D47: 0.11681186 | E47: 0.14425282 | F47: 0.16945605 | G47: 0.19193238 | H47: 0.21488159 | I47: 0.23463131 | J47: 0.35691564 | K47: 0.43630784 | M47: -0.04376041 | N47: -0.07936026 | O47: -0.10702784 | P47: -0.13232092 | Q47: -0.15481214 | R47: -0.17702646 | S47: -0.19958364 | T47: -0.32031173 | U47: -0.40035087
B48: 0.015583457 | C48: 0.065072902 | D48: 0.091958977 | E48: 0.11668464 | F48: 0.13631107 | G48: 0.15486953 | H48: 0.17176676 | I48: 0.19114702 | J48: 0.2881566 | K48: 0.34192504 | M48: -0.034325168 | N48: -0.063538846 | O48: -0.084253824 | P48: -0.10448024 | Q48: -0.12173125 | R48: -0.14106331 | S48: -0.15947055 | T48: -0.25440345 | U48: -0.31126817
B49: 0.39340092 | C49: 0.26967466 | D49: 0.20043445 | E49: 0.14179857 | F49: 0.095927993 | G49: 0.04550364 | H49: 0.0031545652 | I49: -0.0403109 | J49: -0.28293761 | K49: -0.43273788 | M49: 0.51705923 | N49: 0.5839888 | O49: 0.64304965 | P49: 0.69322158 | Q49: 0.74164781 | R49: 0.78309258 | S49: 0.82395073 | T49: 1.0669272 | U49: 1.2189708
B50: 0.092743013 | C50: 0.076605313 | D50: 0.067817757 | E50: 0.058654432 | F50: 0.050598678 | G50: 0.046269673 | H50: 0.039782327 | I50: 0.033683414 | J50: 0.0033114264 | K50: -0.015905205 | M50: 0.10996899 | N50: 0.12082666 | O50: 0.1266853 | P50: 0.13400779 | Q50: 0.1397705 | R50: 0.14524101 | S50: 0.15068187 | T50: 0.18400502 | U50: 0.20120797
B51: 0.38318713 | C51: 0.30197339 | D51: 0.25506864 | E51: 0.22155003 | F51: 0.18459668 | G51: 0.15907823 | H51: 0.12682103 | I51: 0.10025535 | J51: -0.055177056 | K51: -0.16127643 | M51: 0.4643458 | N51: 0.51358432 | O51: 0.5469441 | P51: 0.57901408 | Q51: 0.60844531 | R51: 0.63979527 | S51: 0.6713612 | T51: 0.82618847 | U51: 0.92874962
A52: SUM | B52: =SUM(B45:B51) -> 1 | C52: =SUM(C45:C51) -> 1 | D52: =SUM(D45:D51) -> 1 | E52: =SUM(E45:E51) -> 1 | F52: =SUM(F45:F51) -> 1 | G52: =SUM(G45:G51) -> 1 | H52: =SUM(H45:H51) -> 1 | I52: =SUM(I45:I51) -> 1 | ... K52: =SUM(K45:K51) -> 1 | M52: =SUM(M45:M51) -> 1 | N52: =SUM(N45:N51) -> 1 | O52: =SUM(O45:O51) -> 1 | P52: =SUM(P45:P51) -> 1 | Q52: =SUM(Q45:Q51) -> 1 | R52: =SUM(R45:R51) -> 1 | S52: =SUM(S45:S51) -> 1 | T52: =SUM(T45:T51) -> 1 | U52: =SUM(U45:U51) -> 1
A54: Variance Portfolio | B54: {=MMULT(MMULT(TRANSPOSE(B$45:B$51),$F$19:$L$25),B$45:B$51)} -> 0.001307091 | C54: {=MMULT(MMULT(TRANSPOSE(C$45:C$51),$F$19:$L$25),C$45:C$51)} -> 0.0016000637 | D54: {=MMULT(MMULT(TRANSPOSE(D$45:D$51),$F$19:$L$25),D$45:D$51)} -> 0.0020250898 | E54: {=MMULT(MMULT(TRANSPOSE(E$45:E$51),$F$19:$L$25),E$45:E$51)} -> 0.0025000999 | F54: {=MMULT(MMULT(TRANSPOSE(F$45:F$51),$F$19:$L$25),F$45:F$51)} -> 0.0030251089 | G54: {=MMULT(MMULT(TRANSPOSE(G$45:G$51),$F$19:$L$25),G$45:G$51)} -> 0.00360012 | H54: {=MMULT(MMULT(TRANSPOSE(H$45:H$51),$F$19:$L$25),H$45:H$51)} -> 0.0042250852 | I54: {=MMULT(MMULT(TRANSPOSE(I$45:I$51),$F$19:$L$25),I$45:I$51)} -> 0.00490005 | ... K54: {=MMULT(MMULT(TRANSPOSE(K$45:K$51),$F$19:$L$25),K$45:K$51)} -> 0.014400232 | M54: {=MMULT(MMULT(TRANSPOSE(M$45:M$51),$F$19:$L$25),M$45:M$51)} -> 0.00160008 | N54: {=MMULT(MMULT(TRANSPOSE(N$45:N$51),$F$19:$L$25),N$45:N$51)} -> 0.0020250757 | O54: {=MMULT(MMULT(TRANSPOSE(O$45:O$51),$F$19:$L$25),O$45:O$51)} -> 0.0025001 | P54: {=MMULT(MMULT(TRANSPOSE(P$45:P$51),$F$19:$L$25),P$45:P$51)} -> 0.003025094 | Q54: {=MMULT(MMULT(TRANSPOSE(Q$45:Q$51),$F$19:$L$25),Q$45:Q$51)} -> 0.0036001185 | R54: {=MMULT(MMULT(TRANSPOSE(R$45:R$51),$F$19:$L$25),R$45:R$51)} -> 0.0042250858 | S54: {=MMULT(MMULT(TRANSPOSE(S$45:S$51),$F$19:$L$25),S$45:S$51)} -> 0.0049001399 | T54: {=MMULT(MMULT(TRANSPOSE(T$45:T$51),$F$19:$L$25),T$45:T$51)} -> 0.010000184 | U54: {=MMULT(MMULT(TRANSPOSE(U$45:U$51),$F$19:$L$25),U$45:U$51)} -> 0.014400237
A55: Expected return Portfoli | B55: {=MMULT($B$13:$H$13,B$45:B$51)} -> 0.0089594352 | C55: {=MMULT($B$13:$H$13,C$45:C$51)} -> 0.013918128 | D55: {=MMULT($B$13:$H$13,D$45:D$51)} -> 0.016722147 | E55: {=MMULT($B$13:$H$13,E$45:E$51)} -> 0.018965739 | F55: {=MMULT($B$13:$H$13,F$45:F$51)} -> 0.020967324 | G55: {=MMULT($B$13:$H$13,G$45:G$51)} -> 0.022832008 | H55: {=MMULT($B$13:$H$13,H$45:H$51)} -> 0.024608815 | I55: {=MMULT($B$13:$H$13,I$45:I$51)} -> 0.026324605 | ... K55: {=MMULT($B$13:$H$13,K$45:K$51)} -> 0.042108789 | M55: {=MMULT($B$13:$H$13,M$45:M$51)} -> 0.0040006029 | N55: {=MMULT($B$13:$H$13,N$45:N$51)} -> 0.001196974 | O55: {=MMULT($B$13:$H$13,O$45:O$51)} -> -0.0010469341 | P55: {=MMULT($B$13:$H$13,P$45:P$51)} -> -0.0030484453 | Q55: {=MMULT($B$13:$H$13,Q$45:Q$51)} -> -0.0049131427 | R55: {=MMULT($B$13:$H$13,R$45:R$51)} -> -0.0066899241 | S55: {=MMULT($B$13:$H$13,S$45:S$51)} -> -0.0084059148 | T55: {=MMULT($B$13:$H$13,T$45:T$51)} -> -0.018051639 | U55: {=MMULT($B$13:$H$13,U$45:U$51)} -> -0.024189912
A56: Standard Deviation Portfolio | B56: =SQRT(B54) -> 0.036153713 | C56: =SQRT(C54) -> 0.040000796 | D56: =SQRT(D54) -> 0.045000997 | E56: =SQRT(E54) -> 0.050000999 | F56: =SQRT(F54) -> 0.05500099 | G56: =SQRT(G54) -> 0.060001 | H56: =SQRT(H54) -> 0.065000655 | I56: =SQRT(I54) -> 0.070000357 | ... K56: =SQRT(K54) -> 0.12000097 | M56: =SQRT(M54) -> 0.040001 | N56: =SQRT(N54) -> 0.045000841 | O56: =SQRT(O54) -> 0.050001 | P56: =SQRT(P54) -> 0.055000854 | Q56: =SQRT(Q54) -> 0.060000987 | R56: =SQRT(R54) -> 0.06500066 | S56: =SQRT(S54) -> 0.070000999 | T56: =SQRT(T54) -> 0.10000092 | U56: =SQRT(U54) -> 0.12000099
A57: Target st.dev | C57: 0.04 | D57: =C57+0.5% -> 0.045 | E57: =D57+0.5% -> 0.05 | F57: =E57+0.5% -> 0.055 | G57: =F57+0.5% -> 0.06 | H57: =G57+0.5% -> 0.065 | I57: =H57+0.5% -> 0.07 | J57: =10% -> 0.1 | K57: 0.12 | M57: =C57 -> 0.04 | N57: =D57 -> 0.045 | O57: =E57 -> 0.05 | P57: =F57 -> 0.055 | Q57: =G57 -> 0.06 | R57: =H57 -> 0.065 | S57: =I57 -> 0.07 | T57: =J57 -> 0.1 | U57: =K57 -> 0.12
A97: 3)
A98: WITH SOLVER | B98: Weights
B99: 0.23341055
B100: 0.15082852
B101: 0.18126637
B102: 0.14498157
...

Sheet Main Data
A1: Name | B1: NVIDIA | C1: Return Nvidia | D1: MICROSOFT | E1: Return Microsoft | F1: APPLE | G1: Return Apple | H1: AMAZON.COM | I1: Return Amazon | J1: JOHNSON & JOHNSON | K1: Return Johnson & Johnson | L1: ALPHABET 'A' | M1: Return Alphabet | N1: COCA COLA | O1: Return Coca Cola | Q1: Return Nvidia | R1: Return Microsoft | S1: Return Apple | T1: Return Amazon | U1: Return Johnson & Johnson | V1: Return Alphabet | W1: Return Coca Cola
A2: 40207 | B2: 0.38475 | D2: 28.18 | F2: 6.859386 | H2: 6.2705 | J2: 62.86 | L2: 13.261451 | N2: 27.125
A3: 40235 | B3: 0.405 | C3: =(B3-B2)/B2 -> 0.052631579 | D3: 28.67 | E3: =(D3-D2)/D2 -> 0.017388219 | F3: 7.3078498 | G3: =(F3-F2)/F2 -> 0.065379589 | H3: 5.92 | I3: =(H3-H2)/H2 -> -0.055896659 | J3: 63 | K3: =(J3-J2)/J2 -> 0.0022271715 | L3: 13.182775 | M3: =(L3-L2)/L2 -> -0.0059327023 | N3: 26.36 | O3: =(N3-N2)/N2 -> -0.028202765 | Q3: 0.052631579 | R3: 0.017388219 | S3: 0.065379589 | T3: -0.055896659 | U3: 0.0022271715 | V3: -0.0059327023 | W3: -0.028202765
A4: 40268 | B4: 0.435 | C4: =(B4-B3)/B3 -> 0.074074074 | D4: 29.2875 | E4: =(D4-D3)/D3 -> 0.021538193 | F4: 8.3928488 | G4: =(F4-F3)/F3 -> 0.14847034 | H4: 6.7885 | I4: =(H4-H3)/H3 -> 0.14670608 | J4: 65.2 | K4: =(J4-J3)/J3 -> 0.034920635 | L4: 14.191753 | M4: =(L4-L3)/L3 -> 0.076537585 | N4: 27.5 | O4: =(N4-N3)/N3 -> 0.043247344 | Q4: 0.074074074 | R4: 0.021538193 | S4: 0.14847034 | T4: 0.14670608 | U4: 0.034920635 | V4: 0.076537585 | W4: 0.043247344
A5: 40298 | B5: 0.39275 | C5: =(B5-B4)/B4 -> -0.097126437 | D5: 30.535 | E5: =(D5-D4)/D4 -> 0.042594964 | F5: 9.3246335 | G5: =(F5-F4)/F4 -> 0.11102128 | H5: 6.855 | I5: =(H5-H4)/H4 -> 0.0097959785 | J5: 64.3 | K5: =(J5-J4)/J4 -> -0.013803681 | L5: 13.155123 | M5: =(L5-L4)/L4 -> -0.073044506 | N5: 26.725 | O5: =(N5-N4)/N4 -> -0.028181818 | Q5: -0.097126437 | R5: 0.042594964 | S5: 0.11102128 | T5: 0.0097959785 | U5: -0.013803681 | V5: -0.073044506 | W5: -0.028181818
A6: 40326 | B6: 0.3285 | C6: =(B6-B5)/B5 -> -0.16359007 | D6: 25.8 | E6: =(D6-D5)/D5 -> -0.15506795 | F6: 9.1742765 | G6: =(F6-F5)/F5 -> -0.016124708 | H6: 6.273 | I6: =(H6-H5)/H5 -> -0.084901532 | J6: 58.3 | K6: =(J6-J5)/J5 -> -0.093312597 | L6: 12.152527 | M6: =(L6-L5)/L5 -> -0.076213394 | N6: 25.7 | O6: =(N6-N5)/N5 -> -0.038353601 | Q6: -0.16359007 | R6: -0.15506795 | S6: -0.016124708 | T6: -0.084901532 | U6: -0.093312597 | V6: -0.076213394 | W6: -0.038353601
A7: 40359 | B7: 0.25525 | C7: =(B7-B6)/B6 -> -0.22298326 | D7: 23.01 | E7: =(D7-D6)/D6 -> -0.10813953 | F7: 8.9832053 | G7: =(F7-F6)/F6 -> -0.020826845 | H7: 5.463 | I7: =(H7-H6)/H6 -> -0.12912482 | J7: 59.06 | K7: =(J7-J6)/J6 -> 0.013036021 | L7: 11.13454 | M7: =(L7-L6)/L6 -> -0.083767477 | N7: 25.06 | O7: =(N7-N6)/N6 -> -0.024902724 | Q7: -0.22298326 | R7: -0.10813953 | S7: -0.020826845 | T7: -0.12912482 | U7: 0.013036021 | V7: -0.083767477 | W7: -0.024902724
A8: 40389 | B8: 0.22975 | C8: =(B8-B7)/B7 -> -0.099902057 | D8: 25.81 | E8: =(D8-D7)/D7 -> 0.12168622 | F8: 9.1874908 | G8: =(F8-F7)/F7 -> 0.022740826 | H8: 5.8945 | I8: =(H8-H7)/H7 -> 0.078985905 | J8: 58.09 | K8: =(J8-J7)/J7 -> -0.016423976 | L8: 12.133008 | M8: =(L8-L7)/L7 -> 0.089672997 | N8: 27.555 | O8: =(N8-N7)/N7 -> 0.099561053 | Q8: -0.099902057 | R8: 0.12168622 | S8: 0.022740826 | T8: 0.078985905 | U8: -0.016423976 | V8: 0.089672997 | W8: 0.099561053
A9: 40421 | B9: 0.233125 | C9: =(B9-B8)/B8 -> 0.01468988 | D9: 23.465 | E9: =(D9-D8)/D8 -> -0.090856257 | F9: 8.6821342 | G9: =(F9-F8)/F8 -> -0.055004859 | H9: 6.2415 | I9: =(H9-H8)/H8 -> 0.058868437 | J9: 57.02 | K9: =(J9-J8)/J8 -> -0.018419694 | L9: 11.261413 | M9: =(L9-L8)/L8 -> -0.071836651 | N9: 27.94125 | O9: =(N9-N8)/N8 -> 0.01401742 | Q9: 0.01468988 | R9: -0.090856257 | S9: -0.055004859 | T9: 0.058868437 | U9: -0.018419694 | V9: -0.071836651 | W9: 0.01401742
A10: 40451 | B10: 0.29205 | C10: =(B10-B9)/B9 -> 0.25276139 | D10: 24.49 | E10: =(D10-D9)/D9 -> 0.04368208 | F10: 10.133918 | G10: =(F10-F9)/F9 -> 0.16721514 | H10: 7.853 | I10: =(H10-H9)/H9 -> 0.25819114 | J10: 61.96 | K10: =(J10-J9)/J9 -> 0.086636268 | L10: 13.1575 | M10: =(L10-L9)/L9 -> 0.16837029 | N10: 29.26 | O10: =(N10-N9)/N9 -> 0.047197244 | Q10: 0.25276139 | R10: 0.04368208 | S10: 0.16721514 | T10: 0.25819114 | U10: 0.086636268 | V10: 0.16837029 | W10: 0.047197244
A11: 40480 | B11: 0.3005125 | C11: =(B11-B10)/B10 -> 0.028976203 | D11: 26.665 | E11: =(D11-D10)/D10 -> 0.08881176 | F11: 10.749275 | G11: =(F11-F10)/F10 -> 0.060722467 | H11: 8.2615 | I11: =(H11-H10)/H10 -> 0.052018337 | J11: 63.74 | K11: =(J11-J10)/J10 -> 0.028728212 | L11: 15.357382 | M11: =(L11-L10)/L10 -> 0.16719603 | N11: 30.66 | O11: =(N11-N10)/N10 -> 0.04784689 | Q11: 0.028976203 | R11: 0.08881176 | S11: 0.060722467 | T11: 0.052018337 | U11: 0.028728212 | V11: 0.16719603 | W11: 0.04784689
A12: 40512 | B12: 0.340225 | C12: =(B12-B11)/B11 -> 0.13214925 | D12: 25.2575 | E12: =(D12-D11)/D11 -> -0.052784549 | F12: 11.112489 | G12: =(F12-F11)/F11 -> 0.033789621 | H12: 8.77 | I12: =(H12-H11)/H11 -> 0.061550566 | J12: 61.55 | K12: =(J12-J11)/J11 -> -0.034358331 | L12: 13.906226 | M12: =(L12-L11)/L11 -> -0.094492423 | N12: 31.585 | O12: =(N12-N11)/N11 -> 0.030169602 | Q12: 0.13214925 | R12: -0.052784549 | S12: 0.033789621 | T12: 0.061550566 | U12: -0.034358331 | V12: -0.094492423 | W12: 0.030169602
A13: 40543 | B13: 0.385 | C13: =(B13-B12)/B12 -> 0.13160409 | D13: 27.91 | E13: =(D13-D12)/D12 -> 0.10501831 | F13: 11.519988 | G13: =(F13-F12)/F12 -> 0.036670416 | H13: 9 | I13: =(H13-H12)/H12 -> 0.02622577 | J13: 61.85 | K13: =(J13-J12)/J12 -> 0.0048740861 | L13: 14.863654 | M13: =(L13-L12)/L12 -> 0.06884886 | N13: 32.885 | O13: =(N13-N12)/N12 -> 0.041158778 | Q13: 0.13160409 | R13: 0.10501831 | S13: 0.036670416 | T13: 0.02622577 | U13: 0.0048740861 | V13: 0.06884886 | W13: 0.041158778
A14: 40574 | B14: 0.598 | C14: =(B14-B13)/B13 -> 0.55324675 | D14: 27.725 | E14: =(D14-D13)/D13 -> -0.0066284486 | F14: 12.118559 | G14: =(F14-F13)/F13 -> 0.051959325 | H14: 8.482 | I14: =(H14-H13)/H13 -> -0.057555556 | J14: 59.77 | K14: =(J14-J13)/J13 -> -0.033629749 | L14: 15.023559 | M14: =(L14-L13)/L13 -> 0.010758119 | N14: 31.425 | O14: =(N14-N13)/N13 -> -0.044397142 | Q14: 0.55324675 | R14: -0.0066284486 | S14: 0.051959325 | T14: -0.057555556 | U14: -0.033629749 | V14: 0.010758119 | W14: -0.044397142
... A188: 45869 | B188: 177.87 | C188: =(B188-B187)/B187 -> 0.12583075 | D188: 533.5 | E188: =(D188-D187)/D187 -> 0.072555839 | F188: 207.57 | G188: =(F188-F187)/F187 -> 0.011697617 | H188: 234.11 | I188: =(H188-H187)/H187 -> 0.067095127 | J188: 164.74 | K188: =(J188-J187)/J187 -> 0.078494272 | L188: 191.9 | M188: =(L188-L187)/L187 -> 0.088917891 | N188: 67.89 | O188: =(N188-N187)/N187 -> -0.040424028 | Q188: 0.12583075 | R188: 0.072555839 | S188: 0.011697617 | T188: 0.067095127 | U188: 0.078494272 | V188: 0.088917891 | W188: -0.040424028
